Workbook

Sheet Income_Profit Analysis
A1: NVDIA Data Source: https://www.macrotrends.net/stocks/charts | R1: INTEL Data Source: https://www.macrotrends.net/stocks/charts
C2: Quarter | D2: Net Income | N2: Quarter | O2: Gross Profit | S2: Quarter | T2: Net Income | AF2: Quarter | AG2: Gross Profit
C3: 46053 | D3: 42960 | F3: Row Labels | G3: NVDIA Net Income | N3: 46053 | O3: 51093 | S3: 46022 | T3: -591 | AF3: 46022 | AG3: 4943
C4: 45961 | D4: 31910 | F4: 2014 | G4: 137 | N4: 45961 | O4: 41849 | S4: 45930 | T4: 4063 | AF4: 45930 | AG4: 5218
C5: 45869 | D5: 26422 | F5: 2015 | G5: 134 | N5: 45869 | O5: 33853 | S5: 45838 | T5: -2918 | V5: Row Labels | W5: Net Income | AF5: 45838 | AG5: 3542
C6: 45777 | D6: 18775 | F6: 2016 | G6: 208 | N6: 45777 | O6: 26668 | S6: 45747 | T6: -821 | V6: 2014 | W6: 11704 | AF6: 45747 | AG6: 4672
C7: 45688 | D7: 22091 | F7: 2017 | G7: 507 | N7: 45688 | O7: 28722 | S7: 45657 | T7: -126 | V7: 2015 | W7: 11420 | AF7: 45657 | AG7: 5584
C8: 45596 | D8: 19309 | F8: 2018 | G8: 1244 | N8: 45596 | O8: 26156 | S8: 45565 | T8: -16639 | V8: 2016 | W8: 10316 | AF8: 45565 | AG8: 1997
C9: 45504 | D9: 16599 | F9: 2019 | G9: 394 | N9: 45504 | O9: 22574 | S9: 45473 | T9: -1610 | V9: 2017 | W9: 9601 | AF9: 45473 | AG9: 4547
C10: 45412 | D10: 14881 | F10: 2020 | G10: 917 | N10: 45412 | O10: 20406 | S10: 45382 | T10: -381 | V10: 2018 | W10: 21053 | AF10: 45382 | AG10: 5217
C11: 45322 | D11: 12286 | F11: 2021 | G11: 1912 | N11: 45322 | O11: 16791 | S11: 45291 | T11: 2669 | V11: 2019 | W11: 21048 | AF11: 45291 | AG11: 7047
C12: 45230 | D12: 9243 | F12: 2022 | G12: 1618 | N12: 45230 | O12: 13400 | S12: 45199 | T12: 297 | V12: 2020 | W12: 20899 | AF12: 45199 | AG12: 6018
C13: 45138 | D13: 6188 | F13: 2023 | G13: 2043 | N13: 45138 | O13: 9462 | S13: 45107 | T13: 1481 | V13: 2021 | W13: 19868 | AF13: 45107 | AG13: 4638
C14: 45046 | D14: 2043 | F14: 2024 | G14: 14881 | N14: 45046 | O14: 4648 | S14: 45016 | T14: -2758 | V14: 2022 | W14: 8014 | AF14: 45016 | AG14: 4008
C15: 44957 | D15: 1414 | F15: 2025 | G15: 18775 | N15: 44957 | O15: 3833 | S15: 44926 | T15: -664 | V15: 2023 | W15: 1689 | AF15: 44926 | AG15: 5500
C16: 44865 | D16: 680 | N16: 44865 | O16: 3177 | S16: 44834 | T16: 1019 | V16: 2024 | W16: -18756 | AF16: 44834 | AG16: 6535
C17: 44773 | D17: 656 | N17: 44773 | O17: 2915 | S17: 44742 | T17: -454 | V17: 2025 | W17: -267 | AF17: 44742 | AG17: 5587
C18: 44681 | D18: 1618 | N18: 44681 | O18: 5431 | S18: 44651 | T18: 8113 | AF18: 44651 | AG18: 9244
C19: 44592 | D19: 3002 | F19: Row Labels | G19: NVDIA Gross Profit | N19: 44592 | O19: 5000 | S19: 44561 | T19: 4623 | AF19: 44561 | AG19: 11009
C20: 44500 | D20: 2464 | F20: 2014 | G20: 2518 | N20: 44500 | O20: 4631 | S20: 44469 | T20: 6823 | AF20: 44469 | AG20: 10746
C21: 44408 | D21: 2374 | F21: 2015 | G21: 2721 | N21: 44408 | O21: 4215 | S21: 44377 | T21: 5061 | V21: Row Labels | W21: Gross Profit | AF21: 44377 | AG21: 11206
C22: 44316 | D22: 1912 | F22: 2016 | G22: 3550 | N22: 44316 | O22: 3629 | S22: 44286 | T22: 3361 | V22: 2014 | W22: 35609 | AF22: 44286 | AG22: 10854
C23: 44227 | D23: 1457 | F23: 2017 | G23: 5324 | N23: 44227 | O23: 3157 | S23: 44196 | T23: 5857 | V23: 2015 | W23: 34679 | AF23: 44196 | AG23: 11348
C24: 44135 | D24: 1336 | F24: 2018 | G24: 7765 | N24: 44135 | O24: 2960 | S24: 44104 | T24: 4276 | V24: 2016 | W24: 36233 | AF24: 44104 | AG24: 9741
C25: 44043 | D25: 622 | F25: 2019 | G25: 5960 | N25: 44043 | O25: 2275 | S25: 44012 | T25: 5105 | V25: 2017 | W25: 39098 | AF25: 44012 | AG25: 10507
C26: 43951 | D26: 917 | F26: 2020 | G26: 9254 | N26: 43951 | O26: 2004 | S26: 43921 | T26: 5661 | V26: 2018 | W26: 43737 | AF26: 43921 | AG26: 12016
C27: 43861 | D27: 951 | F27: 2021 | G27: 15632 | N27: 43861 | O27: 2015 | S27: 43830 | T27: 6905 | V27: 2019 | W27: 42140 | AF27: 43830 | AG27: 11878
C28: 43769 | D28: 899 | F28: 2022 | G28: 16523 | N28: 43769 | O28: 1916 | S28: 43738 | T28: 5990 | V28: 2020 | W28: 43612 | AF28: 43738 | AG28: 11295
C29: 43677 | D29: 552 | F29: 2023 | G29: 31343 | N29: 43677 | O29: 1541 | S29: 43646 | T29: 4179 | V29: 2021 | W29: 43815 | AF29: 43646 | AG29: 9878
C30: 43585 | D30: 394 | F30: 2024 | G30: 85927 | N30: 43585 | O30: 1296 | S30: 43555 | T30: 3974 | V30: 2022 | W30: 26866 | AF30: 43555 | AG30: 9089
C31: 43496 | D31: 566 | F31: 2025 | G31: 131092 | N31: 43496 | O31: 1207 | S31: 43465 | T31: 5195 | V31: 2023 | W31: 21711 | AF31: 43465 | AG31: 11227
C32: 43404 | D32: 1230 | N32: 43404 | O32: 1921 | S32: 43373 | T32: 6398 | V32: 2024 | W32: 17345 | AF32: 43373 | AG32: 12360
C33: 43312 | D33: 1101 | N33: 43312 | O33: 1975 | S33: 43281 | T33: 5006 | V33: 2025 | W33: 18375 | AF33: 43281 | AG33: 10419
C34: 43220 | D34: 1244 | N34: 43220 | O34: 2068 | S34: 43190 | T34: 4454 | AF34: 43190 | AG34: 9731
C35: 43131 | D35: 1119 | N35: 43131 | O35: 1801 | S35: 43100 | T35: -687 | AF35: 43100 | AG35: 10778
C36: 43039 | D36: 838 | N36: 43039 | O36: 1569 | S36: 43008 | T36: 4516 | AF36: 43008 | AG36: 10064
C37: 42947 | D37: 583 | N37: 42947 | O37: 1302 | S37: 42916 | T37: 2808 | AF37: 42916 | AG37: 9096
C38: 42855 | D38: 507 | N38: 42855 | O38: 1150 | S38: 42825 | T38: 2964 | AF38: 42825 | AG38: 9160
C39: 42766 | D39: 655 | N39: 42766 | O39: 1303 | S39: 42735 | T39: 3562 | AF39: 42735 | AG39: 10147
C40: 42674 | D40: 542 | N40: 42674 | O40: 1183 | S40: 42643 | T40: 3378 | AF40: 42643 | AG40: 9983
...

Sheet Growth Rate Analysis
J1: NVDIA | N1: INTEL
A2: Year | B2: NVDIA Profit Growth Rate | C2: INTEL Profit Growth Rate | D2: INTEL Net Income Growth | E2: NVDIA Net Income Growth | J2: Row Labels | K2: NVDIA Net Income | L2: YOY Net Income Growth | N2: Row Labels | O2: INTEL Net Income | P2: YoY Net Income Growth
A3: 2014 | J3: 2014 | K3: 585 | N3: 2014 | O3: 11704
A4: 2015 | B4: 0.080619539 | C4: -0.026116993 | D4: -0.024265208 | E4: 0.023931624 | J4: 2015 | K4: 599 | L4: 0.023931624 | N4: 2015 | O4: 11420 | P4: -0.024265208
A5: 2016 | B5: 0.3046674 | C5: 0.044810981 | D5: -0.096672504 | E5: 1.0350584 | J5: 2016 | K5: 1219 | L5: 1.0350584 | N5: 2016 | O5: 10316 | P5: -0.096672504
A6: 2017 | B6: 0.49971831 | C6: 0.079071565 | D6: -0.06930981 | E6: 1.11895 | J6: 2017 | K6: 2583 | L6: 1.11895 | N6: 2017 | O6: 9601 | P6: -0.06930981
A7: 2018 | B7: 0.45848986 | C7: 0.11865057 | D7: 1.1927924 | E7: 0.81726674 | J7: 2018 | K7: 4694 | L7: 0.81726674 | N7: 2018 | O7: 21053 | P7: 1.1927924
A8: 2019 | B8: -0.23245332 | C8: -0.036513707 | D8: -0.00023749584 | E8: -0.48636557 | J8: 2019 | K8: 2411 | L8: -0.48636557 | N8: 2019 | O8: 21048 | P8: -0.00023749584
A9: 2020 | B9: 0.55268456 | C9: 0.034931182 | D9: -0.0070790574 | E9: 0.58689341 | J9: 2020 | K9: 3826 | L9: 0.58689341 | N9: 2020 | O9: 20899 | P9: -0.0070790574
A10: 2021 | B10: 0.68921547 | C10: 0.0046546822 | D10: -0.049332504 | E10: 1.1450601 | J10: 2021 | K10: 8207 | L10: 1.1450601 | N10: 2021 | O10: 19868 | P10: -0.049332504
A11: 2022 | B11: 0.056998465 | C11: -0.38683099 | D11: -0.59663781 | E11: -0.27427806 | J11: 2022 | K11: 5956 | L11: -0.27427806 | N11: 2022 | O11: 8014 | P11: -0.59663781
A12: 2023 | B12: 0.89693155 | C12: -0.19187821 | D12: -0.78924382 | E12: 2.1712559 | J12: 2023 | K12: 18888 | L12: 2.1712559 | N12: 2023 | O12: 1689 | P12: -0.78924382
A13: 2024 | B13: 1.7415053 | C13: -0.20109622 | D13: -12.104796 | E13: 2.3394219 | J13: 2024 | K13: 63075 | L13: 2.3394219 | N13: 2024 | O13: -18756 | P13: -12.104796
A14: 2025 | B14: 0.52562058 | C14: 0.059383108 | D14: -0.98576456 | E14: 0.57269917 | J14: 2025 | K14: 99198 | L14: 0.57269917 | N14: 2025 | O14: -267 | P14: -0.98576456
J17: Row Labels | K17: NVDIA Gross Profit | L17: Yoy Growth Rate - Gross Profit | N17: Row Labels | O17: INTEL - Gross Profit | P17: YOY Growth Rate - Gross Profit
J18: 2014 | K18: 2518 | N18: 2014 | O18: 35609
J19: 2015 | K19: 2721 | L19: 0.080619539 | N19: 2015 | O19: 34679 | P19: -0.026116993
J20: 2016 | K20: 3550 | L20: 0.3046674 | N20: 2016 | O20: 36233 | P20: 0.044810981
J21: 2017 | K21: 5324 | L21: 0.49971831 | N21: 2017 | O21: 39098 | P21: 0.079071565
J22: 2018 | K22: 7765 | L22: 0.45848986 | N22: 2018 | O22: 43737 | P22: 0.11865057
J23: 2019 | K23: 5960 | L23: -0.23245332 | N23: 2019 | O23: 42140 | P23: -0.036513707
J24: 2020 | K24: 9254 | L24: 0.55268456 | N24: 2020 | O24: 43612 | P24: 0.034931182
J25: 2021 | K25: 15632 | L25: 0.68921547 | N25: 2021 | O25: 43815 | P25: 0.0046546822
J26: 2022 | K26: 16523 | L26: 0.056998465 | N26: 2022 | O26: 26866 | P26: -0.38683099
J27: 2023 | K27: 31343 | L27: 0.89693155 | N27: 2023 | O27: 21711 | P27: -0.19187821
J28: 2024 | K28: 85927 | L28: 1.7415053 | N28: 2024 | O28: 17345 | P28: -0.20109622
J29: 2025 | K29: 131092 | L29: 0.52562058 | N29: 2025 | O29: 18375 | P29: 0.059383108
M31: NVDIA Profit Growth Rate | N31: NVDIA Income Growth | O31: INTEL Growth Rate - Gross Profit | P31: INTEL Revenue Growth
M33: 0.080619539 | N33: 0.023931624 | O33: -0.026116993 | P33: -0.024265208
M34: 0.3046674 | N34: 1.0350584 | O34: 0.044810981 | P34: -0.096672504
M35: 0.49971831 | N35: 1.11895 | O35: 0.079071565 | P35: -0.06930981
L36: 2018 | M36: 0.45848986 | N36: 0.81726674 | O36: 0.11865057 | P36: 1.1927924
L37: 2019 | M37: -0.23245332 | N37: -0.48636557 | O37: -0.036513707 | P37: -0.00023749584
L38: 2020 | M38: 0.55268456 | N38: 0.58689341 | O38: 0.034931182 | P38: -0.0070790574
L39: 2021 | M39: 0.68921547 | N39: 1.1450601 | O39: 0.0046546822 | P39: -0.049332504
L40: 2022 | M40: 0.056998465 | N40: -0.27427806 | O40: -0.38683099 | P40: -0.59663781
L41: 2023 | M41: 0.89693155 | N41: 2.1712559 | O41: -0.19187821 | P41: -0.78924382
L42: 2024 | M42: 1.7415053 | N42: 2.3394219 | O42: -0.20109622 | P42: -12.104796
L43: 2025 | M43: 0.52562058 | N43: 0.57269917 | O43: 0.059383108 | P43: -0.98576456

Sheet Summary Dashboard
A1: NVIDIA vs. Intel - Financial Performance Analysis (2014–2025)
A3: Year | B3: NVIDIA Net Income | C3: NVIDIA Gross Profit | D3: Intel Net Income | E3: Intel Gross Profit | F3: NVIDIA NI Growth | G3: Intel NI Growth | H3: NVIDIA vs Intel NI Ratio
A4: 2014 | B4: 585 | C4: 2518 | D4: 11704 | E4: 35609 | F4: - | G4: - | H4: =IF(D4<>0,B4/D4,"N/A") -> 0.049982912
A5: 2015 | B5: 599 | C5: 2721 | D5: 11420 | E5: 34679 | F5: =(B5-B4)/ABS(B4) -> 0.023931624 | G5: =(D5-D4)/ABS(D4) -> -0.024265208 | H5: =IF(D5<>0,B5/D5,"N/A") -> 0.052451839
A6: 2016 | B6: 1219 | C6: 3550 | D6: 10316 | E6: 36233 | F6: =(B6-B5)/ABS(B5) -> 1.0350584 | G6: =(D6-D5)/ABS(D5) -> -0.096672504 | H6: =IF(D6<>0,B6/D6,"N/A") -> 0.11816596
A7: 2017 | B7: 2583 | C7: 5324 | D7: 9601 | E7: 39098 | F7: =(B7-B6)/ABS(B6) -> 1.11895 | G7: =(D7-D6)/ABS(D6) -> -0.06930981 | H7: =IF(D7<>0,B7/D7,"N/A") -> 0.26903448
A8: 2018 | B8: 4694 | C8: 7765 | D8: 21053 | E8: 43737 | F8: =(B8-B7)/ABS(B7) -> 0.81726674 | G8: =(D8-D7)/ABS(D7) -> 1.1927924 | H8: =IF(D8<>0,B8/D8,"N/A") -> 0.2229611
A9: 2019 | B9: 2411 | C9: 5960 | D9: 21048 | E9: 42140 | F9: =(B9-B8)/ABS(B8) -> -0.48636557 | G9: =(D9-D8)/ABS(D8) -> -0.00023749584 | H9: =IF(D9<>0,B9/D9,"N/A") -> 0.1145477
A10: 2020 | B10: 3826 | C10: 9254 | D10: 20899 | E10: 43612 | F10: =(B10-B9)/ABS(B9) -> 0.58689341 | G10: =(D10-D9)/ABS(D9) -> -0.0070790574 | H10: =IF(D10<>0,B10/D10,"N/A") -> 0.18307096
A11: 2021 | B11: 8207 | C11: 15632 | D11: 19868 | E11: 43815 | F11: =(B11-B10)/ABS(B10) -> 1.1450601 | G11: =(D11-D10)/ABS(D10) -> -0.049332504 | H11: =IF(D11<>0,B11/D11,"N/A") -> 0.4130763
A12: 2022 | B12: 5956 | C12: 16523 | D12: 8014 | E12: 26866 | F12: =(B12-B11)/ABS(B11) -> -0.27427806 | G12: =(D12-D11)/ABS(D11) -> -0.59663781 | H12: =IF(D12<>0,B12/D12,"N/A") -> 0.7431994
A13: 2023 | B13: 18888 | C13: 31343 | D13: 1689 | E13: 21711 | F13: =(B13-B12)/ABS(B12) -> 2.1712559 | G13: =(D13-D12)/ABS(D12) -> -0.78924382 | H13: =IF(D13<>0,B13/D13,"N/A") -> 11.182948
A14: 2024 | B14: 63075 | C14: 85927 | D14: -18756 | E14: 17345 | F14: =(B14-B13)/ABS(B13) -> 2.3394219 | G14: =(D14-D13)/ABS(D13) -> -12.104796 | H14: =IF(D14<>0,B14/D14,"N/A") -> -3.3629239
A15: 2025 | B15: 99198 | C15: 131092 | D15: -267 | E15: 18375 | F15: =(B15-B14)/ABS(B14) -> 0.57269917 | G15: =(D15-D14)/ABS(D14) -> 0.98576456 | H15: =IF(D15<>0,B15/D15,"N/A") -> -371.52809
A16: Total / Avg | B16: =SUM(B4:B15) -> 211241 | C16: =SUM(C4:C15) -> 317609 | D16: =SUM(D4:D15) -> 116589 | E16: =SUM(E4:E15) -> 403220 | F16: =AVERAGE(F5:F15) -> 0.8227176 | G16: =AVERAGE(G5:G15) -> -1.0508197

Sheet Relevant Matrics
A1: CAGR Analysis by Era (Compound Annual Growth Rate)
A2: Era | B2: Period | C2: No. of Years | D2: NVIDIA NI Start ($M) | E2: NVIDIA NI End ($M) | F2: NVIDIA CAGR | G2: Intel NI Start ($M) | H2: Intel NI End ($M) | I2: Intel CAGR | J2: Winner
A3: Full Period | B3: 2014–2025 | C3: 11 | D3: ='Summary Dashboard'!B4 -> 585 | E3: ='Summary Dashboard'!B15 -> 99198 | F3: =IFERROR((E3/D3)^(1/C3)-1,"N/A") -> 0.59465931 | G3: ='Summary Dashboard'!D4 -> 11704 | H3: ='Summary Dashboard'!D15 -> -267 | I3: =IFERROR((H3/G3)^(1/C3)-1,"N/A") -> -1.7091586 | J3: =IFERROR(IF(ISNUMBER(F3),IF(ISNUMBER(I3),IF(F3>I3,"✅ NVIDIA","✅ Intel"),"✅ NVIDIA"),"✅ Intel"),"-") -> ✅ NVIDIA
A4: Pre-AI Era | B4: 2014–2019 | C4: 5 | D4: ='Summary Dashboard'!B5 -> 599 | E4: ='Summary Dashboard'!B9 -> 2411 | F4: =IFERROR((E4/D4)^(1/C4)-1,"N/A") -> 0.32115593 | G4: ='Summary Dashboard'!D4 -> 11704 | H4: ='Summary Dashboard'!D9 -> 21048 | I4: =IFERROR((H4/G4)^(1/C4)-1,"N/A") -> 0.12454103 | J4: =IFERROR(IF(ISNUMBER(F4),IF(ISNUMBER(I4),IF(F4>I4,"✅ NVIDIA","✅ Intel"),"✅ NVIDIA"),"✅ Intel"),"-") -> ✅ NVIDIA
A5: AI Boom Era | B5: 2019–2025 | C5: 6 | D5: ='Summary Dashboard'!B9 -> 2411 | E5: ='Summary Dashboard'!B15 -> 99198 | F5: =IFERROR((E5/D5)^(1/C5)-1,"N/A") -> 0.85802242 | G5: ='Summary Dashboard'!D9 -> 21048 | H5: ='Summary Dashboard'!D15 -> -267 | I5: =IFERROR((H5/G5)^(1/C5)-1,"N/A") -> N/A | J5: =IFERROR(IF(ISNUMBER(F5),IF(ISNUMBER(I5),IF(F5>I5,"✅ NVIDIA","✅ Intel"),"✅ NVIDIA"),"✅ Intel"),"-") -> ✅ NVIDIA
A6: Peak Comparison | B6: 2021–2025 | C6: 4 | D6: ='Summary Dashboard'!B11 -> 8207 | E6: ='Summary Dashboard'!B15 -> 99198 | F6: =IFERROR((E6/D6)^(1/C6)-1,"N/A") -> 0.86457399 | G6: ='Summary Dashboard'!D11 -> 19868 | H6: ='Summary Dashboard'!D15 -> -267 | I6: =IFERROR((H6/G6)^(1/C6)-1,"N/A") -> N/A | J6: =IFERROR(IF(ISNUMBER(F6),IF(ISNUMBER(I6),IF(F6>I6,"✅ NVIDIA","✅ Intel"),"✅ NVIDIA"),"✅ Intel"),"-") -> ✅ NVIDIA
A11: Cumulative Growth Index (Base = 100 in 2014)
A12: Year | B12: NVIDIA NI ($M) | C12: Intel NI ($M) | D12: NVIDIA GP ($M) | E12: Intel GP ($M) | F12: NVIDIA NI Index | G12: Intel NI Index | H12: NVIDIA GP Index | I12: Intel GP Index | J12: NI Index Spread
A13: 2014 | B13: 585 | C13: 11704 | D13: 2518 | E13: 35609 | F13: =IFERROR(B13/$B$13*100,"-") -> 100 | G13: =IFERROR(C13/$C$13*100,"-") -> 100 | H13: =IFERROR(D13/$D$13*100,"-") -> 100 | I13: =IFERROR(E13/$E$13*100,"-") -> 100 | J13: =IFERROR(F13-G13,"-") -> 0
A14: 2015 | B14: 599 | C14: 11420 | D14: 2721 | E14: 34679 | F14: =IFERROR(B14/$B$13*100,"-") -> 102.39316 | G14: =IFERROR(C14/$C$13*100,"-") -> 97.573479 | H14: =IFERROR(D14/$D$13*100,"-") -> 108.06195 | I14: =IFERROR(E14/$E$13*100,"-") -> 97.388301 | J14: =IFERROR(F14-G14,"-") -> 4.8196832
A15: 2016 | B15: 1219 | C15: 10316 | D15: 3550 | E15: 36233 | F15: =IFERROR(B15/$B$13*100,"-") -> 208.37607 | G15: =IFERROR(C15/$C$13*100,"-") -> 88.140807 | H15: =IFERROR(D15/$D$13*100,"-") -> 140.98491 | I15: =IFERROR(E15/$E$13*100,"-") -> 101.75237 | J15: =IFERROR(F15-G15,"-") -> 120.23526
A16: 2017 | B16: 2583 | C16: 9601 | D16: 5324 | E16: 39098 | F16: =IFERROR(B16/$B$13*100,"-") -> 441.53846 | G16: =IFERROR(C16/$C$13*100,"-") -> 82.031784 | H16: =IFERROR(D16/$D$13*100,"-") -> 211.43765 | I16: =IFERROR(E16/$E$13*100,"-") -> 109.79808 | J16: =IFERROR(F16-G16,"-") -> 359.50668
A17: 2018 | B17: 4694 | C17: 21053 | D17: 7765 | E17: 43737 | F17: =IFERROR(B17/$B$13*100,"-") -> 802.39316 | G17: =IFERROR(C17/$C$13*100,"-") -> 179.87867 | H17: =IFERROR(D17/$D$13*100,"-") -> 308.37967 | I17: =IFERROR(E17/$E$13*100,"-") -> 122.82569 | J17: =IFERROR(F17-G17,"-") -> 622.51449
A18: 2019 | B18: 2411 | C18: 21048 | D18: 5960 | E18: 42140 | F18: =IFERROR(B18/$B$13*100,"-") -> 412.13675 | G18: =IFERROR(C18/$C$13*100,"-") -> 179.83595 | H18: =IFERROR(D18/$D$13*100,"-") -> 236.69579 | I18: =IFERROR(E18/$E$13*100,"-") -> 118.34087 | J18: =IFERROR(F18-G18,"-") -> 232.3008
A19: 2020 | B19: 3826 | C19: 20899 | D19: 9254 | E19: 43612 | F19: =IFERROR(B19/$B$13*100,"-") -> 654.01709 | G19: =IFERROR(C19/$C$13*100,"-") -> 178.56288 | H19: =IFERROR(D19/$D$13*100,"-") -> 367.5139 | I19: =IFERROR(E19/$E$13*100,"-") -> 122.47466 | J19: =IFERROR(F19-G19,"-") -> 475.45421
A20: 2021 | B20: 8207 | C20: 19868 | D20: 15632 | E20: 43815 | F20: =IFERROR(B20/$B$13*100,"-") -> 1402.906 | G20: =IFERROR(C20/$C$13*100,"-") -> 169.75393 | H20: =IFERROR(D20/$D$13*100,"-") -> 620.81017 | I20: =IFERROR(E20/$E$13*100,"-") -> 123.04474 | J20: =IFERROR(F20-G20,"-") -> 1233.1521
A21: 2022 | B21: 5956 | C21: 8014 | D21: 16523 | E21: 26866 | F21: =IFERROR(B21/$B$13*100,"-") -> 1018.1197 | G21: =IFERROR(C21/$C$13*100,"-") -> 68.472317 | H21: =IFERROR(D21/$D$13*100,"-") -> 656.19539 | I21: =IFERROR(E21/$E$13*100,"-") -> 75.447218 | J21: =IFERROR(F21-G21,"-") -> 949.64734
A22: 2023 | B22: 18888 | C22: 1689 | D22: 31343 | E22: 21711 | F22: =IFERROR(B22/$B$13*100,"-") -> 3228.7179 | G22: =IFERROR(C22/$C$13*100,"-") -> 14.430964 | H22: =IFERROR(D22/$D$13*100,"-") -> 1244.7577 | I22: =IFERROR(E22/$E$13*100,"-") -> 60.970541 | J22: =IFERROR(F22-G22,"-") -> 3214.287
A23: 2024 | B23: 63075 | C23: -18756 | D23: 85927 | E23: 17345 | F23: =IFERROR(B23/$B$13*100,"-") -> 10782.051 | G23: =IFERROR(C23/$C$13*100,"-") -> -160.2529 | H23: =IFERROR(D23/$D$13*100,"-") -> 3412.5099 | I23: =IFERROR(E23/$E$13*100,"-") -> 48.709596 | J23: =IFERROR(F23-G23,"-") -> 10942.304
A24: 2025 | B24: 99198 | C24: -267 | D24: 131092 | E24: 18375 | F24: =IFERROR(B24/$B$13*100,"-") -> 16956.923 | G24: =IFERROR(C24/$C$13*100,"-") -> -2.2812714 | H24: =IFERROR(D24/$D$13*100,"-") -> 5206.1954 | I24: =IFERROR(E24/$E$13*100,"-") -> 51.602123 | J24: =IFERROR(F24-G24,"-") -> 16959.204
A27: Rolling 3-Year Average Net Income
A28: Year | B28: NVIDIA NI ($M) | C28: Intel NI ($M) | D28: NVIDIA 3-Yr Avg | E28: Intel 3-Yr Avg
A29: 2014 | B29: 585 | C29: 11704 | D29: — | E29: —
A30: 2015 | B30: 599 | C30: 11420 | D30: — | E30: —
A31: 2016 | B31: 1219 | C31: 10316 | D31: =AVERAGE(B29:B31) -> 801 | E31: =AVERAGE(C29:C31) -> 11146.667
A32: 2017 | B32: 2583 | C32: 9601 | D32: =AVERAGE(B30:B32) -> 1467 | E32: =AVERAGE(C30:C32) -> 10445.667
A33: 2018 | B33: 4694 | C33: 21053 | D33: =AVERAGE(B31:B33) -> 2832 | E33: =AVERAGE(C31:C33) -> 13656.667
A34: 2019 | B34: 2411 | C34: 21048 | D34: =AVERAGE(B32:B34) -> 3229.3333 | E34: =AVERAGE(C32:C34) -> 17234
A35: 2020 | B35: 3826 | C35: 20899 | D35: =AVERAGE(B33:B35) -> 3643.6667 | E35: =AVERAGE(C33:C35) -> 21000
A36: 2021 | B36: 8207 | C36: 19868 | D36: =AVERAGE(B34:B36) -> 4814.6667 | E36: =AVERAGE(C34:C36) -> 20605
A37: 2022 | B37: 5956 | C37: 8014 | D37: =AVERAGE(B35:B37) -> 5996.3333 | E37: =AVERAGE(C35:C37) -> 16260.333
A38: 2023 | B38: 18888 | C38: 1689 | D38: =AVERAGE(B36:B38) -> 11017 | E38: =AVERAGE(C36:C38) -> 9857
A39: 2024 | B39: 63075 | C39: -18756 | D39: =AVERAGE(B37:B39) -> 29306.333 | E39: =AVERAGE(C37:C39) -> -3017.6667
A40: 2025 | B40: 99198 | C40: -267 | D40: =AVERAGE(B38:B40) -> 60387 | E40: =AVERAGE(C38:C40) -> -5778
A49: Year | B49: NVDIA GP | C49: INTEL GP
A50: 2014 | B50: 2518 | C50: 35609
A51: 2015 | B51: 2721 | C51: 34679
A52: 2016 | B52: 3550 | C52: 36233
A53: 2017 | B53: 5324 | C53: 39098
A54: 2018 | B54: 7765 | C54: 43737
...

Sheet Dashboad
B2: 📊 NVIDIA vs INTEL — Financial Performance Dashboard (2014–2025)
B3: CAGR Analysis | Cumulative Growth Index | Rolling 3-Year Average | Net Income & Gross Profit Trends
B5: ▶ KEY METRICS & CAGR HIGHLIGHTS (FY 2025 — Live from Sheet4)
B6: NVIDIA Net Income 2025 (Sheet4!B24) | E6: Intel Net Income 2025 (Sheet4!C24) | H6: NVIDIA Gross Profit 2025 (Sheet4!D24) | K6: Intel Gross Profit 2025 (Sheet4!E24)
B7: =[1]Sheet4!B24 -> 99198 | E7: =[1]Sheet4!C24 -> -267 | H7: =[1]Sheet4!D24 -> 131092 | K7: =[1]Sheet4!E24 -> 18375
B9: NVIDIA CAGR — Full Period (Sheet4!F3) | E9: Intel CAGR — Full Period (Sheet4!I3) | H9: NVIDIA CAGR — AI Boom Era (Sheet4!F5) | K9: Intel CAGR — AI Boom Era (Sheet4!I5)
B10: =[1]Sheet4!F3 -> 0.59465931 | E10: =[1]Sheet4!I3 -> -1.7091586 | H10: =[1]Sheet4!F5 -> 0.85802242 | K10: =IF(ISNUMBER([1]Sheet4!I5),[1]Sheet4!I5,"N/A") -> N/A
B12: ▶ CHARTS (Data sourced from Sheet4)
